Workbook

Sheet About
A1: IELSR — Indian Electronic Literature Scholarship Repository
A2: A CELL-style bibliographic database of critical writing on electronic literature in India and by Indian scholars. Release 1.0 · compiled 25 September 2026.
A4: Purpose | B4: To give the field of Indian e-lit a citable, filterable record of its critical writing, modelled on the Consortium on Electronic Literature (CELL) and ELMCIP Knowledge Base practice of treating critical writing, creative works and people as linked records.
A5: Scope | B5: (1) Scholarship on e-lit and digital literatures in India; (2) e-lit scholarship by Indian scholars on global works; (3) a small 'Related' tranche of Indian DH infrastructure writing that the e-lit literature depends on. Games and platform literature are included where authors frame them as digital literature.
A6: Core corpus | B6: Works by Shanmugapriya T, Samya Brata Roy, K. Kavitha, Justy Joseph, Simran Bhimjyani, Mehulkumar Desai, Prakruti Bhatt, Kavisha Alagiya; Souvik Mukherjee (2017 article only, as instructed); and every identified article in NRHM vol. 32 no. 2–3, 'India, Digital, LiteratureS: forms and (dis)contents'.
A7: Sheets | B7: Critical Writing = master records (IEL-###). NRHM Special Issue = table of contents. Creative Works = works discussed (W-##), cross-referenced to records. Scholars = authority file with live record counts. Dashboard = formula-driven statistics. Verification Log = leads, conflicts and exclusions.
A8: Record status | B8: Verified = checked against publisher/author page. Partially verified = core facts confirmed, one or more fields (pages, issue, DOI) unconfirmed. To verify = citation lead only.
A9: Abstracts | B9: All abstracts are the cataloguer's own summaries, written for discovery. Consult the original for quotation.
A10: Known conflicts | B10: IEL-003 (JCLA vol. 42 issue and pages differ across sources); IEL-008 (2023 vs 2024 date); issue pagination for three NRHM articles. Details in each record's Notes and the Verification Log.
A11: Not harvested | B11: ELMCIP's 'Indian Electronic Literature' collection and some ResearchGate pages refused automated access; items there should be cross-checked manually.
A12: How to extend | B12: Add a row to Critical Writing using the next IEL number and the dropdowns for Type, Scope and Status. Dashboard and Scholars counts update automatically.

Sheet Dashboard
A1: Dashboard
A2: All figures are formulas over the Critical Writing sheet and update as records are added.
A4: Total records
A5: Critical Writing records | B5: =COUNTA('Critical Writing'!A5:A500) -> 50
A6: Verified | B6: =COUNTIF('Critical Writing'!V5:V500,"Verified") -> 38
A7: Partially verified | B7: =COUNTIF('Critical Writing'!V5:V500,"Partially verified") -> 12
A8: Creative works indexed | B8: =COUNTA('Creative Works'!A5:A500) -> 21
A9: Records in NRHM special issue | B9: =COUNTIF('Critical Writing'!G5:G500,"New Review of Hypermedia and Multimedia") -> 9
A11: By scope category
A12: Category | B12: Records | C12: Share
A13: Adjacent: games & digital narrative | B13: =COUNTIF('Critical Writing'!$R$5:$R$500,A13) -> 3 | C13: =IF($B$5=0,0,B13/$B$5) -> 0.06
A14: Global e-lit (by Indian scholars) | B14: =COUNTIF('Critical Writing'!$R$5:$R$500,A14) -> 8 | C14: =IF($B$5=0,0,B14/$B$5) -> 0.16
A15: Indian e-lit: anthologies & curation | B15: =COUNTIF('Critical Writing'!$R$5:$R$500,A15) -> 2 | C15: =IF($B$5=0,0,B15/$B$5) -> 0.04
A16: Indian e-lit: creative practice & documentation | B16: =COUNTIF('Critical Writing'!$R$5:$R$500,A16) -> 1 | C16: =IF($B$5=0,0,B16/$B$5) -> 0.02
A17: Indian e-lit: eco-e-lit | B17: =COUNTIF('Critical Writing'!$R$5:$R$500,A17) -> 5 | C17: =IF($B$5=0,0,B17/$B$5) -> 0.1
A18: Indian e-lit: field formation | B18: =COUNTIF('Critical Writing'!$R$5:$R$500,A18) -> 8 | C18: =IF($B$5=0,0,B18/$B$5) -> 0.16
A19: Indian e-lit: forms & genres | B19: =COUNTIF('Critical Writing'!$R$5:$R$500,A19) -> 2 | C19: =IF($B$5=0,0,B19/$B$5) -> 0.04
A20: Indian e-lit: institutions & publishing | B20: =COUNTIF('Critical Writing'!$R$5:$R$500,A20) -> 4 | C20: =IF($B$5=0,0,B20/$B$5) -> 0.08
A21: Indian e-lit: marginal & vernacular voices | B21: =COUNTIF('Critical Writing'!$R$5:$R$500,A21) -> 2 | C21: =IF($B$5=0,0,B21/$B$5) -> 0.04
A22: Indian e-lit: pedagogy | B22: =COUNTIF('Critical Writing'!$R$5:$R$500,A22) -> 3 | C22: =IF($B$5=0,0,B22/$B$5) -> 0.06
A23: Related: DH infrastructure | B23: =COUNTIF('Critical Writing'!$R$5:$R$500,A23) -> 5 | C23: =IF($B$5=0,0,B23/$B$5) -> 0.1
A24: Theory of e-lit (by Indian scholars) | B24: =COUNTIF('Critical Writing'!$R$5:$R$500,A24) -> 7 | C24: =IF($B$5=0,0,B24/$B$5) -> 0.14
A26: By year
A27: Category | B27: Records | C27: Share
A28: 2017 | B28: =COUNTIF('Critical Writing'!$C$5:$C$500,A28) -> 1 | C28: =IF($B$5=0,0,B28/$B$5) -> 0.02
A29: 2018 | B29: =COUNTIF('Critical Writing'!$C$5:$C$500,A29) -> 2 | C29: =IF($B$5=0,0,B29/$B$5) -> 0.04
A30: 2019 | B30: =COUNTIF('Critical Writing'!$C$5:$C$500,A30) -> 2 | C30: =IF($B$5=0,0,B30/$B$5) -> 0.04
A31: 2020 | B31: =COUNTIF('Critical Writing'!$C$5:$C$500,A31) -> 2 | C31: =IF($B$5=0,0,B31/$B$5) -> 0.04
A32: 2021 | B32: =COUNTIF('Critical Writing'!$C$5:$C$500,A32) -> 2 | C32: =IF($B$5=0,0,B32/$B$5) -> 0.04
A33: 2022 | B33: =COUNTIF('Critical Writing'!$C$5:$C$500,A33) -> 6 | C33: =IF($B$5=0,0,B33/$B$5) -> 0.12
A34: 2023 | B34: =COUNTIF('Critical Writing'!$C$5:$C$500,A34) -> 3 | C34: =IF($B$5=0,0,B34/$B$5) -> 0.06
A35: 2024 | B35: =COUNTIF('Critical Writing'!$C$5:$C$500,A35) -> 6 | C35: =IF($B$5=0,0,B35/$B$5) -> 0.12
A36: 2025 | B36: =COUNTIF('Critical Writing'!$C$5:$C$500,A36) -> 10 | C36: =IF($B$5=0,0,B36/$B$5) -> 0.2
A37: 2026 | B37: =COUNTIF('Critical Writing'!$C$5:$C$500,A37) -> 16 | C37: =IF($B$5=0,0,B37/$B$5) -> 0.32
A39: By publication type
A40: Category | B40: Records | C40: Share
A41: Anthology (edited collection of creative works) | B41: =COUNTIF('Critical Writing'!$F$5:$F$500,A41) -> 2 | C41: =IF($B$5=0,0,B41/$B$5) -> 0.04
A42: Blog post | B42: =COUNTIF('Critical Writing'!$F$5:$F$500,A42) -> 1 | C42: =IF($B$5=0,0,B42/$B$5) -> 0.02
A43: Book chapter | B43: =COUNTIF('Critical Writing'!$F$5:$F$500,A43) -> 5 | C43: =IF($B$5=0,0,B43/$B$5) -> 0.1
A44: Book review | B44: =COUNTIF('Critical Writing'!$F$5:$F$500,A44) -> 2 | C44: =IF($B$5=0,0,B44/$B$5) -> 0.04
...

Sheet Critical Writing
A1: Critical Writing — master records
A2: One row per publication. Filter by Scope, Scholar cluster, Year or Status.
A4: Record ID | B4: Author(s) | C4: Year | D4: Date / online | E4: Title | F4: Publication type | G4: Container (journal / book / event) | H4: Editors / section | I4: Vol. | J4: Issue | K4: Pages | L4: Publisher | M4: DOI | N4: URL | O4: Abstract (cataloguer summary) | P4: Keywords / tags | Q4: Creative works discussed | R4: Scope category | S4: Scholar cluster | T4: Review status | U4: Access | V4: Record status | W4: Verification source | X4: Cataloguer notes
A5: IEL-001 | B5: Mukherjee, Souvik | C5: 2017 | D5: Spring 2017 | E5: “No Country for E-Lit?” – India and Electronic Literature | F5: Journal article | G5: Hyperrhiz: New Media Cultures | H5: Special Topic: Globalizing Electronic Literature | J5: 16 | L5: Hyperrhiz (NCSU) | M5: 10.20415/hyp/016.e08 | N5: https://hyperrhiz.io/hyperrhiz16/essays/8-mukherjee-absent-presence.html | O5: Foundational diagnosis of the relative absence of e-lit in India. Reads the Digital India programme's omission of digital culture, the late arrival of computing and the Internet, cost barriers to Storyspace-era hypertexts, and STEM-oriented schooling as causes; locates proto-nonlinear precedents in Kavad, Hari Katha and dastangoi, and flags Twine and DH courses as openings. | P5: absence; Digital India; interactive fiction; nonlinearity; Kavad; dastangoi; pedagogy; Twine | Q5: We Are Angry (Prickett 2015); Unrest; Somewhere (Studio Oleomingus); Kolaveri Di; Hok Kolorob | R5: Indian e-lit: field formation | S5: Mukherjee (2017 only, per brief) | T5: Peer-reviewed journal | U5: Open access | V5: Verified | W5: Publisher page (hyperrhiz.io), fetched 25 Sep 2026 | X5: Per brief, only this Mukherjee item is catalogued. Cited as a baseline by nearly every later record.
A6: IEL-002 | B6: Shanmugapriya T; Menon, Nirmala | C6: 2018 | D6: Aug 2018 | E6: Locating New Literary Practices in Indian Digital Spaces | F6: Journal article (peer-reviewed conference proceeding) | G6: MATLIT: Materialities of Literature | I6: 6 | J6: 1 | K6: 159–174 | L6: Imprensa da Universidade de Coimbra | M6: 10.14195/2182-8830_6-1_11 | N6: https://impactum-journals.uc.pt/matlit/article/download/2182-8830_6-1_11/4678 | O6: Maps Indian digital literary practices then unrecognised as e-lit (SMS novels, social-media poetry, flash and Twitter fiction) and argues for continuity with multimodal precolonial forms such as Pattachitra, Ragamala painting and Chitra Kavi. Notes India's absence from ELC3. | P6: SMS novel; twitterfiction; social media narrative; Chitra Kavi; Pattachitra; multimodality; ELC3 | Q6: Cloak Room (Ro Gue, SMS novel, 2004) | R6: Indian e-lit: field formation | S6: Shanmugapriya T | T6: Peer-reviewed | U6: Open access | V6: Verified | W6: Author CV (shanmugapriya.com); Academia.edu record | X6: Developed from paper at ELO 2017, Universidade Fernando Pessoa, Porto (19–22 Jul 2017). CV gives variant title 'Locating New Literary Practices/Expressions…'.
A7: IEL-005 | B7: Shanmugapriya T; Campbell, Andy; Menon, Nirmala | C7: 2018 | D7: 2018 | E7: THANNER KUHAI ‘The Water Cave’ – A VR Poetry Experience | F7: Magazine article | G7: Digimag | J7: 78 | K7: 20–26 | L7: Digicult | N7: http://www.digicult.it/wp-content/uploads/digimag78.pdf | O7: Maker's account of a bilingual (Tamil/English) VR poem built with Dreaming Methods; one of the earliest Indian-authored immersive e-lit works to be documented critically. | P7: VR poetry; Tamil; bilingual e-lit; immersive narrative; practice-based research | Q7: Thanner Kuhai / The Water Cave (Campbell, Shanmugapriya T & Rushfirth, 2018) | R7: Indian e-lit: creative practice & documentation | S7: Shanmugapriya T | T7: Non-peer-reviewed | U7: Open access | V7: Verified | W7: Author CV | X7: Also presented at DHAI 2018 (IIM Indore) and Languages INTER Networks, Lancaster 2019.
A8: IEL-003 | B8: Shanmugapriya T; Menon, Nirmala | C8: 2019 | D8: 2019 (issue dated 2019; posted Oct 2020) | E8: First and Second Waves of Indian Electronic Literature | F8: Journal article | G8: Journal of Comparative Literature and Aesthetics | I8: 42 | J8: 3 or 4 — see notes | K8: 51–57 or 63–71 — see notes | L8: Vishvanatha Kaviraja Institute of Comparative Literature and Aesthetics | N8: https://jcla.in/wp-content/uploads/2020/10/JCLA-42.4_E-Lit_Nirmala-Menon.pdf | O8: Proposes an India-specific periodisation: a first wave (2004–2009) of SMS novels with little public or academic reception, followed by a second wave. Argues that Hayles's and Flores's generational models do not map onto Indian timelines. | P8: periodisation; waves; generations; SMS novel; Hayles; Flores; postcolonial timelines | Q8: Cloak Room (2004); Neelakannukal (2006); Deaf Heaven (2009) | R8: Indian e-lit: field formation | S8: Shanmugapriya T | T8: Peer-reviewed | U8: Open access (PDF) | V8: Partially verified | W8: Author CV; ResearchGate record; citing works | X8: CITATION CONFLICT: author CV says vol.42 no.3 (2019) pp.51–57; Roy (IEL-013) cites vol.42 no.4, pp.63–71; PDF filename says 42.4; one ELO abstract dates it 2020. Check the printed issue before citing.
A9: IEL-004 | B9: Shanmugapriya T; Menon, Nirmala; Campbell, Andy | C9: 2019 | D9: Online Nov 2018; print Sep 2019 | E9: An Introduction to the Functioning Process of Embedded Paratext of Digital Literature: Technoeikon of Digital Poetry | F9: Journal article | G9: Digital Scholarship in the Humanities | I9: 34 | J9: 3 | K9: 646–660 | L9: Oxford University Press | M9: 10.1093/llc/fqy064 | N9: https://doi.org/10.1093/llc/fqy064 | O9: Coins 'technoeikon' for the embedded paratext of born-digital works (kinetic text, image, sound, interface), traces its lineage through pre-print and print cultures, and tests it on Andy Campbell's Dim O'Gauble, with a response from Campbell. | P9: technoeikon; paratext; digital poetry; kinetic text; media-specific analysis | Q9: Dim O'Gauble (Andy Campbell, 2007) | R9: Theory of e-lit (by Indian scholars) | S9: Shanmugapriya T | T9: Peer-reviewed | U9: Subscription (author copy on ResearchGate) | V9: Verified | W9: Author CV; DSH DOI
A10: IEL-033 | B10: Shanmugapriya T; Menon, Nirmala | C10: 2020 | D10: 2020 | E10: Infrastructure and Social Interaction: Situated Research Practices in Digital Humanities in India | F10: Journal article | G10: Digital Humanities Quarterly | I10: 14 | J10: 3 | L10: ADHO | O10: Examines how infrastructure and social interaction shape DH research practice in India; background for the infrastructural arguments in e-lit scholarship. | P10: infrastructure; situated practice; DH in India | R10: Related: DH infrastructure | S10: Shanmugapriya T | T10: Peer-reviewed | U10: Open access | V10: Partially verified | W10: Author CV | X10: Included as context, not e-lit proper.
A11: IEL-034 | B11: Menon, Nirmala; Shanmugapriya T | C11: 2020 | D11: 2020 | E11: Digital humanities in India: Pedagogy, Publishing and Practices | F11: Book chapter | G11: Exploring Digital Humanities in India | H11: Kalra, Nidhi; Dodd, Maya | L11: Routledge | O11: Surveys DH pedagogy, publishing and practice in India; context for later e-lit pedagogy work. | P11: DH pedagogy; publishing; India | R11: Related: DH infrastructure | S11: Shanmugapriya T | T11: Peer-reviewed (edited volume) | U11: Subscription | V11: Partially verified | W11: Author CV | X11: Context only.
A12: IEL-039 | B12: Ramya, R.; Rukmini, S. | C12: 2021 | D12: 27 Jun 2021 | E12: Literature in New Media: A Comparative Study of Literary Affordances of Lance Olsen’s “10:01” in Traditional and Digital Medium | F12: Journal article | G12: Rupkatha Journal on Interdisciplinary Studies in Humanities | I12: 13 | J12: 2 | L12: Rupkatha | N12: https://rupkatha.com/v13n245/ | O12: Compares the print and digital versions of Olsen's 10:01 to isolate medium-specific literary affordances. | P12: affordances; print vs digital; media-specific analysis | Q12: 10:01 (Lance Olsen & Tim Guthrie) | R12: Global e-lit (by Indian scholars) | S12: Other Indian scholars | T12: Peer-reviewed | U12: Open access | V12: Verified | W12: Rupkatha category listing
A13: IEL-040 | B13: Roy, Gitanjali | C13: 2021 | D13: 15 Jun 2021 | E13: Performance Space of the Digital Performer/Reader inside Andy Campbell and Judi Alston’s Digital Fiction The Nightingale’s Playground | F13: Journal article | G13: Rupkatha Journal on Interdisciplinary Studies in Humanities | I13: 13 | L13: Rupkatha | N13: https://rupkatha.com/v13n232/ | O13: Treats the reader of a Dreaming Methods digital fiction as a performer and analyses the performance space the work constructs. | P13: performance; reader as performer; digital fiction; Dreaming Methods | Q13: The Nightingale's Playground (Campbell & Alston) | R13: Global e-lit (by Indian scholars) | S13: Other Indian scholars | T13: Peer-reviewed | U13: Open access | V13: Partially verified | W13: Rupkatha category listing | X13: Issue number not shown in listing.
A14: IEL-006 | B14: Shanmugapriya T; Sutton, Deborah | C14: 2022 | D14: Feb 2022 | E14: Electronic literature as a method and as a disseminative tool for environmental calamity through a case study of digital poetry ‘Lost water! Remains Scape?’ | F14: Journal article (conference gathering) | G14: electronic book review | H14: Gathering: Platform [Post?] Pandemic (ELO 2021) | L14: electronic book review | N14: https://electronicbookreview.com/publications/electronic-literature-as-a-method-and-as-a-disseminative-tool-for-environmental-calamity-through-a-case-study-of-digital-poetry-lost-water-remains-scape/ | O14: Positions e-lit as both research method and public dissemination for an AHRC water-scarcity project in Coimbatore; the bilingual digital poem juxtaposes 2D/3D reconstructions of historic waterscapes with present-day imagery. Surveys adjacent Indian works (HyperPoetry Level 1; Darshan Diversion). | P14: digital environmental humanities; eco e-lit; water scarcity; Tamil; method; dissemination | Q14: Lost Water! Remainscape? (2022); HyperPoetry Level 1 (Ghosh & Gajapure); Darshan Diversion (Padmini Ray Murray) | R14: Indian e-lit: eco-e-lit | S14: Shanmugapriya T | T14: Peer-reviewed (ebr gathering) | U14: Open access | V14: Verified | W14: ebr publication page; ebr gathering index | X14: Author CV lists a shorter title ('“Lost water! Remains Scape?”: Transformation Waterscapes in Coimbatore…'); ebr index uses both. Catalogued under the ebr article title.
A15: IEL-007 | B15: Shanmugapriya T; Sutton, Deborah | C15: 2022 | D15: 2022 | E15: The Digital Poetics of Lost Waterscapes in Coimbatore, South India | F15: Book chapter | G15: Routledge Handbook of the Digital Environmental Humanities | H15: Bergmann, L.; Crampsie, A.; Dixon, D.; Hartman, S.; Legg, R.; Ludlow, F.; Travis, C. | L15: Routledge | O15: Companion chapter to IEL-006 theorising digital poetics as a way of narrating environmental loss in South India. | P15: digital poetics; environmental humanities; Coimbatore; waterscapes | Q15: Lost Water! Remainscape? | R15: Indian e-lit: eco-e-lit | S15: Shanmugapriya T | T15: Peer-reviewed (edited volume) | U15: Subscription | V15: Partially verified | W15: Author profiles (IIT Indore DH Lab; UofT DHN Q&A) | X15: Pages and DOI not confirmed.
A16: IEL-013 | B16: Roy, Samya Brata | C16: 2022 | D16: 9 Jan 2022 | E16: Indian Solo Electronic Writing and its Modernist Print Anxiety | F16: Journal article | G16: electronic book review | L16: electronic book review | M16: 10.7273/sj5h-fa44 | N16: https://electronicbookreview.com/publications/indian-solo-electronic-writing-and-its-modernist-print-anxiety/ | O16: Isolates 'solo' (single-creator, non-collaborative) electronic writing as a subset that reveals what is possible under the digital divide, and reads its lingering attachment to print modernism. Builds on Mukherjee and Shanmugapriya & Menon. | P16: solo electronic writing; digital divide; modernism; print anxiety; Instagram poetry; blogs | Q16: TINTA Poetry (Instagram); An Unstable Extravert (blog); Exploring 'The Waste Land' | R16: Indian e-lit: forms & genres | S16: Roy, Samya Brata | T16: Peer-reviewed | U16: Open access | V16: Verified | W16: ebr page; GITAM faculty page
A17: IEL-015 | B17: Roy, Samya Brata | C17: 2022 | D17: Dec 2022 | E17: Hitman 2 and its Spectre of Mumbai: A City Lost in Translation | F17: Book chapter | G17: Literary Cultures and Digital Humanities in India | H17: Zaidi, Nishat; Pue, A. Sean | K17: ch. 21 | L17: Routledge India | M17: 10.4324/9781003354246-21 | N17: https://www.taylorfrancis.com/chapters/edit/10.4324/9781003354246-21/hitman-2-spectre-mumbai-samya-brata-roy | O17: Reads the representation of Mumbai in a AAA game as a problem of cultural translation; adjacent to e-lit via digital narrative and game studies. | P17: videogames; Mumbai; representation; translation; digital narrative | Q17: Hitman 2 (IO Interactive, 2018) | R17: Adjacent: games & digital narrative | S17: Roy, Samya Brata | T17: Peer-reviewed (edited volume) | U17: Subscription | V17: Verified | W17: GITAM faculty page; Routledge TOC | X17: DOI added in round 3 (from Roy's Press Start author bio).
A18: IEL-018 | B18: Joseph, Justy; Menon, Nirmala | C18: 2022 | D18: 24 Nov 2022 | E18: Electronic Literature in India: Where Is It? Does It Even Exist? | F18: Book chapter | G18: Literary Cultures and Digital Humanities in India | H18: Zaidi, Nishat; Pue, A. Sean | K18: 296–312 (ch. 22) | L18: Routledge India | M18: 10.4324/9781003354246-22 | N18: https://www.taylorfrancis.com/chapters/edit/10.4324/9781003354246-22/electronic-literature-india-justy-joseph-nirmala-menon | O18: Examines the pandemic-era shift to digital-first publishing and reading in India and locates digital literature in regional languages and English, together with its reception. | P18: digital-first publishing; COVID-19; regional languages; reception; e-publishing | R18: Indian e-lit: field formation | S18: Joseph, Justy | T18: Peer-reviewed (edited volume) | U18: Subscription | V18: Verified | W18: Taylor & Francis chapter page; NRHM editorial | X18: Routledge TOC lists it as ch.17 in one version; chapter DOI suffix is -22.
A19: IEL-035 | B19: Rizvi, Zahra; Chauhan, R.; Pue, A. Sean; Zaidi, Nishat | C19: 2022 | D19: 2022 | E19: Minimal computing for exploring Indian poetics | F19: Journal article | G19: Digital Humanities Quarterly | I19: 16 | J19: 2 | L19: ADHO | M19: 10.63744/nbdmreacad3y | O19: Minimal-computing approaches to Indian poetics; listed by the special-issue editors among foundational studies of Indian digital narrative. | P19: minimal computing; poetics; Urdu/Hindi; DH | R19: Related: DH infrastructure | S19: Rizvi, Zahra (SI co-editor) | T19: Peer-reviewed | U19: Open access | V19: Partially verified | W19: NRHM editorial reference list | X19: DOI as given in the editorial.
A20: IEL-008 | B20: Menon, Nirmala; Shanmugapriya T; Joseph, Justy; Sutton, Deborah (eds.) | C20: 2023 | D20: 13 Dec 2023 | E20: Indian Electronic Literature Anthology: Volume I | F20: Anthology (edited collection of creative works) | H20: Menon; Shanmugapriya T; Joseph; Sutton | I20: I | L20: IITI KSHIP (with Ubiquity Press) | M20: 10.57004/book1 | N20: https://indianelitanthology.iiti.ac.in/ | O20: First multilingual anthology of Indian e-lit; curates 17 works with editorial framing. Functions as a canon-forming and preservation instrument for the field. | P20: anthology; curation; multilingual e-lit; canon; preservation; KSHIP | Q20: 17 works (see anthology PDF) | R20: Indian e-lit: anthologies & curation | S20: Shanmugapriya T; Joseph, Justy | T20: Editorial curation | U20: Open access | V20: Verified | W20: Editors' profiles; anthology site; Lancaster research portal | X20: Some sources date publication 2024; DOI metadata and Lancaster portal give 13/12/2023.
A21: IEL-014 | B21: Ensslin, Astrid; Roy, Samya Brata | C21: 2023 | D21: 24 May 2023 | E21: Electronic LiteratureS as Postcomparative Media | F21: Journal article | G21: CompLit. Journal of European Literature, Arts and Society | I21: 5 | J21: 2023-1 | K21: 145–171 | L21: Classiques Garnier | M21: 10.48611/isbn.978-2-406-14861-6.p.0145 | O21: Theorises e-lit in the plural as a fluid, culturally situated phenomenon that unsettles comparatist frameworks; supplies the 'LiteratureS' concept adopted by the NRHM special issue. | P21: postcomparative; plurality; world e-lit; comparative literature; theory | R21: Theory of e-lit (by Indian scholars) | S21: Roy, Samya Brata | T21: Peer-reviewed | U21: Subscription | V21: Verified | W21: GITAM faculty page; NRHM editorial reference list | X21: GITAM page gives pp.145–172.
A22: IEL-036 | B22: Joseph, Justy; Palanisamy, Kaviarasu; Justin, Jyothi; Menon, Nirmala | C22: 2023 | D22: 2023 | E22: Digital Humanities Workshops in India: Effective Organizing Pedagogies and Sustainable Contributions to Academia | F22: Book chapter | G22: Digital Humanities Workshops (Routledge) | K22: 48–55 | L22: Taylor & Francis | M22: 10.4324/9781003301097-6 | O22: Defines DH workshops as a training arena and assesses their pedagogical design and sustainability in India; context for e-lit workshop pedagogy (cf. IEL-024, IEL-025). | P22: workshops; DH pedagogy; capacity building | R22: Related: DH infrastructure | S22: Joseph, Justy | T22: Peer-reviewed (edited volume) | U22: Subscription | V22: Verified | W22: Publication list in Joseph's PhD thesis (IIT Indore, 2024) | X22: Round 3: corrected year (2022→2023), container and pages from the author's own thesis list.
A23: IEL-010 | B23: Shanmugapriya T | C23: 2024 | D23: 18 Jul 2024 | E23: A Glimpse into Past And Present Challenges: Indian Electronic Literature | F23: Conference presentation | G23: ELO (Un)linked 2024, University of Central Florida | L23: STARS, UCF | N23: https://stars.library.ucf.edu/elo2024/narrativeandworlds/schedule/3/ | O23: Takes stock of growth (dra.ft curation, Indian contributions to ELC4, the Anthology) and asks which obstacles beyond the digital divide and low awareness have been missed. | P23: challenges; digital divide; ELC4; dra.ft; field review | Q23: Indian Electronic Literature Anthology Vol. I | R23: Indian e-lit: field formation | S23: Shanmugapriya T | T23: Juried conference | U23: Open (abstract) | V23: Verified | W23: STARS record
A24: IEL-011 | B24: Shanmugapriya T | C24: 2024 | D24: 18–20 Jan 2024 | E24: Barriers in access: Issues concerning digital creative arts in India | F24: Keynote | G24: ELO (Un)conference: Access Works! 2024 | L24: Electronic Literature Organization | O24: Keynote on infrastructural, linguistic and institutional barriers to producing and accessing digital creative arts in India. | P24: access; infrastructure; digital creative arts; keynote | R24: Indian e-lit: field formation | S24: Shanmugapriya T | T24: Invited | U24: n/a | V24: Partially verified | W24: IIT Indore DH Lab profile | X24: No recording/text located.
A25: IEL-012 | B25: Roy, Samya Brata; Shanmugapriya T | C25: 2024 | D25: 18 Jul 2024 | E25: Publishing Electronic Literature Research as Precarious Academics | F25: Workshop | G25: ELO (Un)linked 2024, University of Central Florida | L25: STARS, UCF | N25: https://stars.library.ucf.edu/elo2024/narrativeandworlds/schedule/21/ | O25: Workshop on the mismatch between digital e-lit research and metric-driven institutional publication demands facing early-career scholars. | P25: scholarly publishing; precarity; research evaluation; early-career | R25: Indian e-lit: institutions & publishing | S25: Roy, Samya Brata; Shanmugapriya T | T25: Juried conference | U25: Open (abstract) | V25: Verified | W25: STARS record | X25: Precursor to IEL-032.
A26: IEL-026 | B26: Bhatt, Prakruti | C26: 2024 | D26: Apr 2024 | E26: Theorizing Third Generation E-lit: An Analysis of the Digital Writing Applications | F26: Conference presentation | G26: Webinar: E-literature: Explorations in Literary Creativity, Dept. of English, Jamia Millia Islamia | L26: ResearchGate (slides) | N26: https://www.researchgate.net/publication/379564363_Theorizing_Third_Generation_E-lit_An_Analysis_of_the_Digital_Writing_Applications | O26: Asks whether outputs of Indian writing apps such as YourQuote and Writco belong to third-generation e-lit, using Hayles's media-specific analysis and Murray's digital literary sphere. | P26: third-generation e-lit; writing apps; YourQuote; Writco; media-specific analysis | Q26: YourQuote; Writco (platforms) | R26: Indian e-lit: forms & genres | S26: Bhatt, Prakruti | T26: Non-peer-reviewed | U26: Open | V26: Verified | W26: ResearchGate record | X26: Grey literature.
A27: IEL-038 | B27: Bhuyan, Pooja; Dutta, Rajashree | C27: 2024 | D27: Dec 2024 | E27: Examining Narrative Possibilities in Hyper-text Fiction: A Study Beyond the Territory of Print Fiction in Quibbling and Patchwork Girl | F27: Journal article | G27: Rupkatha Journal on Interdisciplinary Studies in Humanities | I27: 16 | J27: 3 | L27: Rupkatha | M27: 10.21659/rupkatha.v16n3.05 | N27: https://rupkatha.com/v16n305/ | O27: Indian scholars reading two canonical Storyspace-era hypertexts for narrative affordances unavailable to print fiction. | P27: hypertext fiction; Storyspace; narrative; Patchwork Girl; Quibbling | Q27: Quibbling (Carolyn Guyer); Patchwork Girl (Shelley Jackson) | R27: Global e-lit (by Indian scholars) | S27: Other Indian scholars | T27: Peer-reviewed | U27: Open access | V27: Verified | W27: Rupkatha category listing
A28: IEL-048 | B28: Roy, Samya Brata | C28: 2024 | D28: 19 Nov 2024 | E28: Review: Videogames in the Indian Subcontinent: Development, Culture(s) and Representations, by Souvik Mukherjee | F28: Book review | G28: Press Start | H28: Issue theme: The Playful Postcolonial: Culturing Videogames in India | I28: 10 | J28: 2 | K28: 67–70 | L28: University of Glasgow | N28: https://press-start.gla.ac.uk/press-start/article/view/300 | O28: Review of Mukherjee's 2022 Bloomsbury monograph on the development, cultures and representations of games in South Asia. | P28: book review; videogames; India; South Asia; postcolonial game studies | R28: Adjacent: games & digital narrative | S28: Roy, Samya Brata | T28: Editorially reviewed | U28: Open access (CC BY) | V28: Verified | W28: Publisher page metadata | X28: Catalogued as Roy's work; the Mukherjee restriction in the brief applies to Mukherjee-authored items, not reviews of them.
A29: IEL-016 | B29: Roy, Samya Brata | C29: 2025 | D29: Online 20 Jan 2025 | E29: e-Sahitya, or the contested emergence of the electronic within the literary in India | F29: Journal article | G29: New Review of Hypermedia and Multimedia | H29: Special Issue: India, Digital, LiteratureS: forms and (dis)contents (eds. S.B. Roy, A. Ensslin, Z. Rizvi, Shanmugapriya T) | I29: 32 | J29: 2–3 | K29: 182–198 | L29: Taylor & Francis | M29: 10.1080/13614568.2025.2453677 | N29: https://doi.org/10.1080/13614568.2025.2453677 | O29: Contrasts ELO-aligned university engagement with e-lit against the print-centred paradigm of the Sahitya Akademi, using interviews, panel records and a library visit, set against the history of English studies and post-independence cultural policy. Ends with a call for investment. | P29: Sahitya Akademi; institutions; English studies; print paradigm; cultural policy; ELO | R29: Indian e-lit: institutions & publishing | S29: Roy, Samya Brata | T29: Peer-reviewed | U29: Subscription | V29: Verified | W29: T&F article page | X29: In NRHM special issue.
A30: IEL-019 | B30: Kavitha, K.; Menon, Nirmala | C30: 2025 | D30: Online 12 Dec 2025 | E30: Trans women’s creative outputs on YouTube as Indian Trans Women Electronic Literature: archiving and amplifying digital narratives | F30: Journal article | G30: New Review of Hypermedia and Multimedia | H30: Special Issue: India, Digital, LiteratureS: forms and (dis)contents (eds. S.B. Roy, A. Ensslin, Z. Rizvi, Shanmugapriya T) | I30: 32 | J30: 2–3 | K30: 168–181 | L30: Taylor & Francis | M30: 10.1080/13614568.2025.2595323 | N30: https://doi.org/10.1080/13614568.2025.2595323 | O30: Argues that poetry films and animated stories by Indian trans women on YouTube qualify as e-lit (multimodal, interactive, narrative) and proposes an Omeka archive to counter algorithmic suppression and weak institutional presence. | P30: trans women; queer e-lit; YouTube; poetry film; Omeka; archiving; marginality | Q30: Trans women's YouTube poetry films and animated stories (corpus) | R30: Indian e-lit: marginal & vernacular voices | S30: Kavitha, K. | T30: Peer-reviewed | U30: Subscription | V30: Verified | W30: T&F article page; NRHM editorial
A31: IEL-020 | B31: Bhimjyani, Simran; Desai, Mehulkumar; Shanmugapriya T | C31: 2025 | D31: Online 18 Sep 2025 | E31: Narrating nature in the digital age: exploring Indian eco-electronic literature | F31: Journal article | G31: New Review of Hypermedia and Multimedia | H31: Special Issue: India, Digital, LiteratureS: forms and (dis)contents (eds. S.B. Roy, A. Ensslin, Z. Rizvi, Shanmugapriya T) | I31: 32 | J31: 2–3 | K31: TBC | L31: Taylor & Francis | M31: 10.1080/13614568.2025.2557808 | N31: https://doi.org/10.1080/13614568.2025.2557808 | O31: Applies ecophenomenological and ecohermeneutic readings to show how multimodality, kinetic image and sound in three Indian works cultivate ecological consciousness about local environmental concerns. | P31: eco-e-lit; ecophenomenology; ecohermeneutics; multimodality; sound; environment | Q31: Blue Is My Favourite Colour (Bhimjyani); Meghadutam (Priti Pandurangan); Lost Water! Remainscape? (Shanmugapriya T) | R31: Indian e-lit: eco-e-lit | S31: Bhimjyani; Desai; Shanmugapriya T | T31: Peer-reviewed | U31: Subscription | V31: Verified | W31: T&F listing; NRHM editorial | X31: Issue pagination not confirmed (13 pp.). Google Scholar: cited by 1 (Sep 2026).
A32: IEL-021 | B32: Fernandez, Geoffrey Bryan; Gaur, Rashmi | C32: 2025 | D32: Online 26 Sep 2025 | E32: Unwriting hegemonic narratives: examining Venba as a decolonial intervention in video game spaces | F32: Journal article | G32: New Review of Hypermedia and Multimedia | H32: Special Issue: India, Digital, LiteratureS: forms and (dis)contents (eds. S.B. Roy, A. Ensslin, Z. Rizvi, Shanmugapriya T) | I32: 32 | J32: 2–3 | K32: TBC | L32: Taylor & Francis | M32: 10.1080/13614568.2025.2562011 | N32: https://doi.org/10.1080/13614568.2025.2562011 | O32: Proposes an 'unwriting' framework to read a Tamil diasporic cooking game as decolonial design, with food, language and gendered labour as carriers of cultural memory. | P32: decolonial game design; Tamil diaspora; food; language; Indian digital literature | Q32: Venba (Visai Games, 2023) | R32: Adjacent: games & digital narrative | S32: Special issue contributor | T32: Peer-reviewed | U32: Subscription | V32: Verified | W32: T&F article page; NRHM editorial | X32: Issue pagination not confirmed.
A33: IEL-022 | B33: Salim, Simi K. | C33: 2025 | D33: Online 20 Nov 2025 | E33: Malayali women’s travel writing in Instagram and digitally mediated cultures of reading | F33: Journal article | G33: New Review of Hypermedia and Multimedia | H33: Special Issue: India, Digital, LiteratureS: forms and (dis)contents (eds. S.B. Roy, A. Ensslin, Z. Rizvi, Shanmugapriya T) | I33: 32 | J33: 2–3 | K33: TBC | L33: Taylor & Francis | M33: 10.1080/13614568.2025.2587150 | N33: https://doi.org/10.1080/13614568.2025.2587150 | O33: Digital-ethnographic study of two Malayali author-influencers whose Instagram travel texts, reels and Bookstagram reviews crossed into print through small Calicut publishers, arguing that vernacular Insta-literature reshapes what counts as 'LiteratureS'. | P33: Instagram; Malayalam; vernacular; Gen Z; Bookstagram; travel writing; author-influencer | Q33: @abreedabanu; @hannamehthar; Karakkam (2023); Kubaku.co (2024) | R33: Indian e-lit: marginal & vernacular voices | S33: Special issue contributor | T33: Peer-reviewed | U33: Subscription | V33: Verified | W33: Author-deposited PDF (Academia.edu)
A34: IEL-023 | B34: Nagpal, Ruchi | C34: 2025 | D34: Online 12 Dec 2025 | E34: Indian digital literature(s): tracing the contours of an emergence | F34: Journal article | G34: New Review of Hypermedia and Multimedia | H34: Special Issue: India, Digital, LiteratureS: forms and (dis)contents (eds. S.B. Roy, A. Ensslin, Z. Rizvi, Shanmugapriya T) | I34: 32 | J34: 2–3 | K34: 89–108 | L34: Taylor & Francis | M34: 10.1080/13614568.2025.2595326 | N34: https://doi.org/10.1080/13614568.2025.2595326 | O34: Treats Indian e-lit as a distinct category within e-lit and traces how its contested definitions extend the question of what literature is; opens from Mukherjee's (2017) endnote. | P34: definition; emergence; category; Indian digital literature | R34: Indian e-lit: field formation | S34: Special issue contributor | T34: Peer-reviewed | U34: Subscription | V34: Verified | W34: T&F article page
A35: IEL-027 | B35: Alagiya, Kavisha Dilipbhai | C35: 2025 | D35: Jan 2025 | E35: From Prompts to Prose: AI-Generated Flash Fiction for Stylistic and Hypertextual Analysis | F35: Journal article | G35: International Journal of Research and Analytical Reviews (IJRAR) | I35: 12 | J35: 1 | K35: 84–89 | L35: IJRAR | N35: https://ijrar.org/papers/IJRAR1DXP017.pdf | O35: Classroom study in which undergraduate groups prompted GPT-4 to produce hyperlinked flash fiction; analyses style and the functionality of embedded links, proposing AI-assisted hypertext as a teaching tool. | P35: AI; generative writing; hypertext; flash fiction; stylistics; pedagogy | R35: Indian e-lit: pedagogy | S35: Alagiya, Kavisha | T35: Journal (review status unverified) | U35: Open access | V35: Verified | W35: Publisher PDF
A36: IEL-037 | B36: Bhimjyani, Simran; Desai, Mehulkumar | C36: 2025 | D36: 23 Apr 2025 | E36: Translating Voyant Tools into Gujarati: Bridging Digital Humanities and Regional Scholarship | F36: Blog post | G36: Voyant Tools blog | L36: Voyant Tools | N36: https://voyant-tools.info/2025/04/23/translating-voyant-tools-into-gujarati-bridging-digital-humanities-and-regional-scholarship/ | O36: Reports the Gujarati localisation of Voyant, the first Indian regional language added to the platform. | P36: localisation; Gujarati; text analysis; regional languages | R36: Related: DH infrastructure | S36: Bhimjyani; Desai | T36: Non-peer-reviewed | U36: Open | V36: Verified | W36: Voyant blog | X36: Context: vernacular tooling for Indian e-lit/DH.
A37: IEL-041 | B37: Desai, Mehulkumar | C37: 2025 | D37: 2025 | E37: Technoeikon | F37: Glossary entry | G37: The Living Glossary of Digital Narrative | L37: Center for Digital Narrative, University of Bergen | N37: https://glossary.cdn.uib.no/ | O37: Defines technoeikon for an international reference glossary as the interplay of image, kinetic text, sound, video and graphic design that animates digital literature — carrying the term coined by Shanmugapriya T, Menon & Campbell (IEL-004) into a field-wide vocabulary. | P37: technoeikon; glossary; terminology; digital literature; multimodality | R37: Theory of e-lit (by Indian scholars) | S37: Desai | T37: Editorially reviewed reference work | U37: Open access | V37: Verified | W37: Glossary site (entry text located); Desai's Google Scholar profile (supplied by user, Sep 2026) | X37: Shows uptake of an India-originated concept in the CDN glossary. Attribution to Desai from Google Scholar; the search snippet did not show the author credit.
A38: IEL-050 | B38: Bhimjyani, Simran; Shanmugapriya T | C38: 2025 | D38: 2025 (month TBC) | E38: Electronic Ecologies: A Study on the Representation of Nature in Indian Electronic Literature | F38: Conference presentation | G38: Global Digital Humanities Symposium 2025 (Michigan State University) | L38: MSU Global DH | N38: https://2025.msuglobaldh.org/schedule/ | O38: Conference version of the eco-e-lit research later published as IEL-020. | P38: eco-e-lit; nature; representation; Indian e-lit | R38: Indian e-lit: eco-e-lit | S38: Bhimjyani; Shanmugapriya T | T38: Juried conference | U38: n/a | V38: Partially verified | W38: Symposium schedule (search snippet; page blocks crawlers) | X38: Confirm date and session.
A39: IEL-009 | B39: Menon, Nirmala; Joseph, Justy; Shanmugapriya T (eds.) | C39: 2026 | D39: Mar 2026 | E39: Indian Electronic Literature Anthology: Volume 2 | F39: Anthology (edited collection of creative works) | H39: Menon; Joseph; Shanmugapriya T | I39: 2 | L39: IIT Indore (JPN National Centre / KSHIP) | N39: https://indianelitanthology.iiti.ac.in/volume-2/ | O39: Second volume with a preface framing e-lit as a domain that both inhabits and extends DH methods; eight works including eco-narratives and campus IF. | P39: anthology; curation; e-lit and DH; eco-e-lit | Q39: Blue is my favourite Colour (Bhimjyani); The Dream of an Insomniac (Niyogi); Zara's Odyssey (S Anas Ahmad); The Sacred Sap (Desai); Gadwal (Padmanabhan); Poemxreader (Andrea); Purrfectly Intertwined (George); Boogy at DU (Goswami) | R39: Indian e-lit: anthologies & curation | S39: Shanmugapriya T; Joseph, Justy; Bhimjyani; Desai | T39: Editorial curation | U39: Open access | V39: Verified | W39: Anthology site (fetched 25 Sep 2026) | X39: Several contributors are also scholars catalogued here (Bhimjyani, Desai, S Anas Ahmad).
A40: IEL-017 | B40: Roy, Samya Brata; Ensslin, Astrid; Rizvi, Zahra; Shanmugapriya T | C40: 2026 | D40: Online 8 Jul 2026 | E40: India, digital, literatureS: forms and (dis)contents | F40: Editorial introduction | G40: New Review of Hypermedia and Multimedia | H40: Special Issue: India, Digital, LiteratureS: forms and (dis)contents (eds. S.B. Roy, A. Ensslin, Z. Rizvi, Shanmugapriya T) | I40: 32 | J40: 2–3 | L40: Taylor & Francis | M40: 10.1080/13614568.2026.2698242 | N40: https://doi.org/10.1080/13614568.2026.2698242 | O40: Frames the issue around a deliberately comma-separated 'India, digital, literatureS' to avoid fixing what counts as Indian, groups contributions into forms, (dis)contents and pedagogy, and reviews prior scholarship from Singh (2016) onward. | P40: special issue; plurality; forms; discontents; historiography | R40: Indian e-lit: field formation | S40: Roy, Samya Brata; Shanmugapriya T | T40: Editorial | U40: Free access | V40: Verified | W40: T&F article page | X40: Key reference list for the whole field; see sheet 'NRHM Special Issue'.
A41: IEL-024 | B41: Shahid, Maria; Ahmad, S. Anas; Ahmad, Bushra; Khan, M. Rizwan | C41: 2026 | D41: Online 16 Mar 2026 | E41: Digital Humanities and Electronic Literature in India: opportunities, challenges, and future directions | F41: Journal article | G41: New Review of Hypermedia and Multimedia | H41: Special Issue: India, Digital, LiteratureS: forms and (dis)contents (eds. S.B. Roy, A. Ensslin, Z. Rizvi, Shanmugapriya T) | I41: 32 | J41: 2–3 | K41: 199–224 | L41: Taylor & Francis | M41: 10.1080/13614568.2026.2643163 | N41: https://doi.org/10.1080/13614568.2026.2643163 | O41: Uses participant data from a GIAN course on DH and e-lit to identify gaps in Indian higher education and recommends curriculum, collaboration and policy responses to linguistic diversity and infrastructure. | P41: higher education; GIAN; curriculum; policy; Digital India; infrastructure | R41: Indian e-lit: pedagogy | S41: Special issue contributor | T41: Peer-reviewed | U41: Subscription | V41: Verified | W41: T&F article page | X41: S. Anas Ahmad is also a creator in Anthology Vol. 2.
...

Sheet NRHM Special Issue
A1: New Review of Hypermedia and Multimedia 32 (2–3), 2026 — India, Digital, LiteratureS: forms and (dis)contents
A2: Guest editors: Samya Brata Roy, Astrid Ensslin, Zahra Rizvi, Shanmugapriya T · Taylor & Francis
A4: Order | B4: Record ID | C4: Author(s) | D4: Title | E4: Pages | F4: Online first | G4: DOI | H4: Editorial grouping (per introduction)
A5: 1 | B5: IEL-017 | C5: Roy; Ensslin; Rizvi; Shanmugapriya T | D5: India, digital, literatureS: forms and (dis)contents (Introduction) | E5: TBC | F5: 8 Jul 2026 | G5: 10.1080/13614568.2026.2698242 | H5: Introduction
A6: 2 | B6: IEL-023 | C6: Nagpal, Ruchi | D6: Indian digital literature(s): tracing the contours of an emergence | E6: 89–108 | F6: 12 Dec 2025 | G6: 10.1080/13614568.2025.2595326 | H6: Forms / definitions
A7: 3 | B7: IEL-020 | C7: Bhimjyani; Desai; Shanmugapriya T | D7: Narrating nature in the digital age: exploring Indian eco-electronic literature | E7: TBC (c.13 pp.) | F7: 18 Sep 2025 | G7: 10.1080/13614568.2025.2557808 | H7: Forms
A8: 4 | B8: IEL-021 | C8: Fernandez; Gaur | D8: Unwriting hegemonic narratives: examining Venba as a decolonial intervention in video game spaces | E8: TBC (c.26 pp.) | F8: 26 Sep 2025 | G8: 10.1080/13614568.2025.2562011 | H8: Forms
A9: 5 | B9: IEL-022 | C9: Salim, Simi K. | D9: Malayali women’s travel writing in Instagram and digitally mediated cultures of reading | E9: TBC (c.20 pp.) | F9: 20 Nov 2025 | G9: 10.1080/13614568.2025.2587150 | H9: Forms
A10: 6 | B10: IEL-019 | C10: Kavitha, K.; Menon, N. | D10: Trans women’s creative outputs on YouTube as Indian Trans Women Electronic Literature | E10: 168–181 | F10: 12 Dec 2025 | G10: 10.1080/13614568.2025.2595323 | H10: Forms / marginal voices
A11: 7 | B11: IEL-016 | C11: Roy, Samya Brata | D11: e-Sahitya, or the contested emergence of the electronic within the literary in India | E11: 182–198 | F11: 20 Jan 2025 | G11: 10.1080/13614568.2025.2453677 | H11: (Dis)contents
A12: 8 | B12: IEL-024 | C12: Shahid; Ahmad; Ahmad; Khan | D12: Digital Humanities and Electronic Literature in India: opportunities, challenges, and future directions | E12: 199–224 | F12: 16 Mar 2026 | G12: 10.1080/13614568.2026.2643163 | H12: (Dis)contents
A13: 9 | B13: IEL-025 | C13: Bhatt, P.K.; Barad, D. | D13: Teaching electronic literature in India: a case study of using Twine for a creative writing workshop | E13: 225–256 | F13: 3 Apr 2026 | G13: 10.1080/13614568.2026.2645116 | H13: Pedagogy
A15: Note | B15: Articles 3–5 are cited in the introduction's reference list; their page spans (c.59 pp. combined) fit the gap between pp.108 and 168, so ordering is inferred. Confirm against the issue TOC.
A16: Articles in issue | B16: =COUNTA(B5:B13) -> 9

Sheet Creative Works
A1: Creative Works — works discussed in the critical record
A2: Cross-referenced to Critical Writing by Record ID. Languages marked 'verify' are unconfirmed.
A4: Work ID | B4: Title | C4: Creator(s) | D4: Year | E4: Form | F4: Language(s) | G4: Publisher / venue | H4: Why it matters | I4: Discussed in
A5: W-01 | B5: Cloak Room | C5: Ro Gue | D5: 2004 | E5: SMS novel | F5: English | G5: 3825media / SMS Junction | H5: Cited as the first Indian SMS novel and start of the 'first wave' | I5: IEL-002; IEL-003
A6: W-02 | B6: Neelakannukal | C6: (author not recorded) | D6: 2006 | E6: SMS novel | F6: Malayalam (verify) | H6: First-wave SMS novel | I6: IEL-003
A7: W-03 | B7: Deaf Heaven | C7: (author not recorded) | D7: 2009 | E7: SMS novel | F7: English (verify) | H7: First-wave SMS novel | I7: IEL-003
A8: W-04 | B8: We Are Angry | C8: Lucy Prickett | D8: 2015 | E8: Digital story | F8: English | G8: weareangry.net | H8: Award-winning digital story on violence against women in India | I8: IEL-001
A9: W-05 | B9: Thanner Kuhai (The Water Cave) | C9: Andy Campbell; Shanmugapriya T; Alex Rushfirth | D9: 2018 | E9: VR poetry | F9: Tamil / English | G9: Dreaming Methods / One to One Development Trust | H9: Bilingual immersive poem | I9: IEL-005
A10: W-06 | B10: Lost Water! Remainscape? | C10: Shanmugapriya T (English); Jagadeesh (Tamil) | D10: 2022 | E10: Digital poetry with game mechanics | F10: Tamil / English | G10: Lancaster University / AHRC | H10: Eco-e-lit on Coimbatore water bodies; exhibited ICIDS 2024 | I10: IEL-006; IEL-007; IEL-020; IEL-032
A11: W-07 | B11: The Lost Oasis | C11: Andy Campbell; Shanmugapriya T | D11: 2024 | E11: Digital poetry / game | F11: English | G11: Dreaming Methods | H11: Collaborative work | I11: IEL-008 (context)
A12: W-08 | B12: Blue Is My Favourite Colour | C12: Simran Bhimjyani | D12: 2026 (Anth. Vol.2) | E12: Eco e-lit | F12: English (verify) | G12: Indian E-Lit Anthology Vol.2 | H12: Analysed as eco-e-lit | I12: IEL-009; IEL-020
A13: W-09 | B13: Meghadutam | C13: Priti Pandurangan | D13: n.d. | E13: Digital adaptation / eco e-lit | F13: (verify) | H13: Analysed as eco-e-lit | I13: IEL-020
A14: W-10 | B14: The Sacred Sap | C14: Mehulkumar Desai | D14: 2026 | E14: E-lit | F14: (verify) | G14: Indian E-Lit Anthology Vol.2 | H14: Creator also a catalogued scholar | I14: IEL-009
A15: W-11 | B15: Zara’s Odyssey: Echoes of Belonging (v1.1) | C15: S Anas Ahmad | D15: 2026 | E15: Interactive narrative | F15: (verify) | G15: Indian E-Lit Anthology Vol.2 | H15: Creator also co-author of IEL-024 | I15: IEL-009
A16: W-12 | B16: Gadwal – A short visual narrative of the town submerged in a climate catastrophe | C16: Arundhathi Padmanabhan | D16: 2026 | E16: Visual narrative | F16: (verify) | G16: Indian E-Lit Anthology Vol.2 | H16: Climate fiction | I16: IEL-009
A17: W-13 | B17: HyperPoetry Level 1 | C17: Srinjoy Ghosh; Kshitij Gajapure | D17: n.d. | E17: Hypertext poetry | F17: English | H17: Continuum theory and hypertext | I17: IEL-006
A18: W-14 | B18: Darshan Diversion | C18: Padmini Ray Murray | D18: n.d. | E18: Game / e-lit | F18: English | H18: Menstruation and temple entry | I18: IEL-006
A19: W-15 | B19: Venba | C19: Visai Games | D19: 2023 | E19: Narrative cooking game | F19: English / Tamil | G19: Visai Games | H19: Tamil diasporic memory; decolonial design | I19: IEL-021
A20: W-16 | B20: Somewhere | C20: Studio Oleomingus | D20: in development (2014–) | E20: Hypertextual point-and-click game | F20: English | G20: Studio Oleomingus | H20: Postcolonial game | I20: IEL-001
A21: W-17 | B21: Unrest | C21: Pyrodactyl Games | D21: 2014 | E21: Indie RPG set in ancient India | F21: English | H21: Nonlinear storytelling | I21: IEL-001
A22: W-18 | B22: Dim O'Gauble | C22: Andy Campbell | D22: 2007 | E22: Digital fiction | F22: English | G22: Dreaming Methods | H22: Case study for 'technoeikon' (non-Indian work) | I22: IEL-004
A23: W-19 | B23: Stone Moons | C23: Deena Larsen | D23: n.d. | E23: Hypertext | F23: English | H23: Reviewed and discussed by Desai | I23: IEL-042; IEL-043
A24: W-20 | B24: Dérivepedia | C24: Talan Memmott | D24: n.d. | E24: Generative / recombinant digital poetry | F24: English | G24: The NEXT (Works on Screen exhibition) | H24: Subject of Desai's exhibition essay | I24: IEL-045
A25: W-21 | B25: Are You There? / Kya Tum Ho Waha | C25: Prakruti Bhatt; Deena Larsen | D25: c.2024–25 | E25: Collaborative hypertext | F25: English / Hindi | H25: Indo-US hypertext collaboration; preceded the Twine workshop | I25: IEL-025

Sheet Scholars
A1: Scholars — authority file
A2: Record counts are live COUNTIF formulas on the Critical Writing author column.
A4: Scholar | B4: Match key (used in formula) | C4: Affiliation (latest known) | D4: ORCID | E4: Role in repository | F4: Records (as author/editor) | G4: Earliest year | H4: Latest year
A5: Shanmugapriya T | B5: Shanmugapriya | C5: Asst. Prof. (Digital Humanities), IIT (ISM) Dhanbad | D5: 0000-0002-1524-429X | E5: Named in brief; SI co-editor; ELO Board; DHARTI Secretary; co-founder ICIDN | F5: =COUNTIF('Critical Writing'!$B$5:$B$500,"*"&B5&"*") -> 21 | G5: =IF(F5=0,"",_xlfn.MINIFS('Critical Writing'!$C$5:$C$500,'Critical Writing'!$B$5:$B$500,"*"&B5&"*")) -> 2018 | H5: =IF(F5=0,"",_xlfn.MAXIFS('Critical Writing'!$C$5:$C$500,'Critical Writing'!$B$5:$B$500,"*"&B5&"*")) -> 2026
A6: Samya Brata Roy | B6: Roy, Samya | C6: Asst. Prof., Dept. of English, GITAM, Hyderabad | D6: 0009-0003-3795-9856 | E6: Named in brief; SI lead editor; co-founder eLitIndia | F6: =COUNTIF('Critical Writing'!$B$5:$B$500,"*"&B6&"*") -> 9 | G6: =IF(F6=0,"",_xlfn.MINIFS('Critical Writing'!$C$5:$C$500,'Critical Writing'!$B$5:$B$500,"*"&B6&"*")) -> 2022 | H6: =IF(F6=0,"",_xlfn.MAXIFS('Critical Writing'!$C$5:$C$500,'Critical Writing'!$B$5:$B$500,"*"&B6&"*")) -> 2026
A7: K. Kavitha | B7: Kavitha | C7: PhD, DH & Publishing Studies Group, IIT Indore | D7: 0009-0009-6834-6992 | E7: Named in brief | F7: =COUNTIF('Critical Writing'!$B$5:$B$500,"*"&B7&"*") -> 1 | G7: =IF(F7=0,"",_xlfn.MINIFS('Critical Writing'!$C$5:$C$500,'Critical Writing'!$B$5:$B$500,"*"&B7&"*")) -> 2025 | H7: =IF(F7=0,"",_xlfn.MAXIFS('Critical Writing'!$C$5:$C$500,'Critical Writing'!$B$5:$B$500,"*"&B7&"*")) -> 2025
A8: Justy Joseph | B8: Joseph, Justy | C8: Visiting Asst. Prof., Ashoka University; CE, KSHIP IIT Indore | E8: Named in brief; Anthology co-editor | F8: =COUNTIF('Critical Writing'!$B$5:$B$500,"*"&B8&"*") -> 4 | G8: =IF(F8=0,"",_xlfn.MINIFS('Critical Writing'!$C$5:$C$500,'Critical Writing'!$B$5:$B$500,"*"&B8&"*")) -> 2022 | H8: =IF(F8=0,"",_xlfn.MAXIFS('Critical Writing'!$C$5:$C$500,'Critical Writing'!$B$5:$B$500,"*"&B8&"*")) -> 2026
A9: Simran Bhimjyani | B9: Bhimjyani | C9: (IIT (ISM) Dhanbad — verify) | E9: Named in brief; creator and scholar | F9: =COUNTIF('Critical Writing'!$B$5:$B$500,"*"&B9&"*") -> 3 | G9: =IF(F9=0,"",_xlfn.MINIFS('Critical Writing'!$C$5:$C$500,'Critical Writing'!$B$5:$B$500,"*"&B9&"*")) -> 2025 | H9: =IF(F9=0,"",_xlfn.MAXIFS('Critical Writing'!$C$5:$C$500,'Critical Writing'!$B$5:$B$500,"*"&B9&"*")) -> 2025
A10: Mehulkumar Desai | B10: Desai | C10: Research scholar, IIT (ISM) Dhanbad | E10: Named in brief; co-founder ICIDN | F10: =COUNTIF('Critical Writing'!$B$5:$B$500,"*"&B10&"*") -> 12 | G10: =IF(F10=0,"",_xlfn.MINIFS('Critical Writing'!$C$5:$C$500,'Critical Writing'!$B$5:$B$500,"*"&B10&"*")) -> 2025 | H10: =IF(F10=0,"",_xlfn.MAXIFS('Critical Writing'!$C$5:$C$500,'Critical Writing'!$B$5:$B$500,"*"&B10&"*")) -> 2026
A11: Souvik Mukherjee | B11: Mukherjee | C11: Presidency University, Kolkata (at 2017) | E11: Named in brief — 2017 article only | F11: =COUNTIF('Critical Writing'!$B$5:$B$500,"*"&B11&"*") -> 1 | G11: =IF(F11=0,"",_xlfn.MINIFS('Critical Writing'!$C$5:$C$500,'Critical Writing'!$B$5:$B$500,"*"&B11&"*")) -> 2017 | H11: =IF(F11=0,"",_xlfn.MAXIFS('Critical Writing'!$C$5:$C$500,'Critical Writing'!$B$5:$B$500,"*"&B11&"*")) -> 2017
A12: Prakruti K. Bhatt | B12: Bhatt, Prakruti | C12: Dept. of English, MKBU, Bhavnagar | E12: Named in brief | F12: =COUNTIF('Critical Writing'!$B$5:$B$500,"*"&B12&"*") -> 2 | G12: =IF(F12=0,"",_xlfn.MINIFS('Critical Writing'!$C$5:$C$500,'Critical Writing'!$B$5:$B$500,"*"&B12&"*")) -> 2024 | H12: =IF(F12=0,"",_xlfn.MAXIFS('Critical Writing'!$C$5:$C$500,'Critical Writing'!$B$5:$B$500,"*"&B12&"*")) -> 2026
A13: Kavisha D. Alagiya | B13: Alagiya | C13: PhD scholar, MKBU, Bhavnagar | E13: Named in brief ('Kavisha') | F13: =COUNTIF('Critical Writing'!$B$5:$B$500,"*"&B13&"*") -> 2 | G13: =IF(F13=0,"",_xlfn.MINIFS('Critical Writing'!$C$5:$C$500,'Critical Writing'!$B$5:$B$500,"*"&B13&"*")) -> 2025 | H13: =IF(F13=0,"",_xlfn.MAXIFS('Critical Writing'!$C$5:$C$500,'Critical Writing'!$B$5:$B$500,"*"&B13&"*")) -> 2026
A14: Nirmala Menon | B14: Menon, Nirmala | C14: Chair Professor, IIT Indore | D14: 0000-0003-0150-5249 | E14: Frequent co-author; Anthology lead editor | F14: =COUNTIF('Critical Writing'!$B$5:$B$500,"*"&B14&"*") -> 11 | G14: =IF(F14=0,"",_xlfn.MINIFS('Critical Writing'!$C$5:$C$500,'Critical Writing'!$B$5:$B$500,"*"&B14&"*")) -> 2018 | H14: =IF(F14=0,"",_xlfn.MAXIFS('Critical Writing'!$C$5:$C$500,'Critical Writing'!$B$5:$B$500,"*"&B14&"*")) -> 2026
A15: Ruchi Nagpal | B15: Nagpal | C15: Maharaja Agrasen College, Univ. of Delhi | E15: SI contributor | F15: =COUNTIF('Critical Writing'!$B$5:$B$500,"*"&B15&"*") -> 1 | G15: =IF(F15=0,"",_xlfn.MINIFS('Critical Writing'!$C$5:$C$500,'Critical Writing'!$B$5:$B$500,"*"&B15&"*")) -> 2025 | H15: =IF(F15=0,"",_xlfn.MAXIFS('Critical Writing'!$C$5:$C$500,'Critical Writing'!$B$5:$B$500,"*"&B15&"*")) -> 2025
A16: Simi K. Salim | B16: Salim | C16: Independent researcher / IIT Madras | E16: SI contributor | F16: =COUNTIF('Critical Writing'!$B$5:$B$500,"*"&B16&"*") -> 1 | G16: =IF(F16=0,"",_xlfn.MINIFS('Critical Writing'!$C$5:$C$500,'Critical Writing'!$B$5:$B$500,"*"&B16&"*")) -> 2025 | H16: =IF(F16=0,"",_xlfn.MAXIFS('Critical Writing'!$C$5:$C$500,'Critical Writing'!$B$5:$B$500,"*"&B16&"*")) -> 2025
A17: Maria Shahid | B17: Shahid | C17: Dept. of English, AMU Aligarh | D17: 0000-0002-4326-5741 | E17: SI contributor | F17: =COUNTIF('Critical Writing'!$B$5:$B$500,"*"&B17&"*") -> 1 | G17: =IF(F17=0,"",_xlfn.MINIFS('Critical Writing'!$C$5:$C$500,'Critical Writing'!$B$5:$B$500,"*"&B17&"*")) -> 2026 | H17: =IF(F17=0,"",_xlfn.MAXIFS('Critical Writing'!$C$5:$C$500,'Critical Writing'!$B$5:$B$500,"*"&B17&"*")) -> 2026
A18: Geoffrey Bryan Fernandez | B18: Fernandez | C18: HSS, IIT Roorkee | E18: SI contributor | F18: =COUNTIF('Critical Writing'!$B$5:$B$500,"*"&B18&"*") -> 1 | G18: =IF(F18=0,"",_xlfn.MINIFS('Critical Writing'!$C$5:$C$500,'Critical Writing'!$B$5:$B$500,"*"&B18&"*")) -> 2025 | H18: =IF(F18=0,"",_xlfn.MAXIFS('Critical Writing'!$C$5:$C$500,'Critical Writing'!$B$5:$B$500,"*"&B18&"*")) -> 2025
A19: Zahra Rizvi | B19: Rizvi | C19: Center for Digital Narrative, Univ. of Bergen | D19: 0000-0001-8874-8731 | E19: SI co-editor | F19: =COUNTIF('Critical Writing'!$B$5:$B$500,"*"&B19&"*") -> 2 | G19: =IF(F19=0,"",_xlfn.MINIFS('Critical Writing'!$C$5:$C$500,'Critical Writing'!$B$5:$B$500,"*"&B19&"*")) -> 2022 | H19: =IF(F19=0,"",_xlfn.MAXIFS('Critical Writing'!$C$5:$C$500,'Critical Writing'!$B$5:$B$500,"*"&B19&"*")) -> 2026
A20: Astrid Ensslin | B20: Ensslin | C20: Univ. of Regensburg | D20: 0000-0003-2189-0025 | E20: SI co-editor (non-Indian collaborator) | F20: =COUNTIF('Critical Writing'!$B$5:$B$500,"*"&B20&"*") -> 2 | G20: =IF(F20=0,"",_xlfn.MINIFS('Critical Writing'!$C$5:$C$500,'Critical Writing'!$B$5:$B$500,"*"&B20&"*")) -> 2023 | H20: =IF(F20=0,"",_xlfn.MAXIFS('Critical Writing'!$C$5:$C$500,'Critical Writing'!$B$5:$B$500,"*"&B20&"*")) -> 2026

Sheet Scholar Activities
A1: Scholar Activities — service, editorial, creative and presentation record
A2: Non-publication activity, kept separate so Critical Writing stays a bibliography. Currently populated for Desai; extend per scholar.
A4: Scholar | B4: Activity type | C4: Description | D4: Date | E4: Source | F4: Status
A5: Desai, Mehulkumar | B5: Organisation | C5: Co-founder, Indian Consortium for Interactive Digital Narratives (ICIDN), with Shanmugapriya T | D5: c.2025– | E5: STARS bios (ELO 2026) | F5: Verified
A6: Desai, Mehulkumar | B6: Organisation | C6: Core-committee member, Electronic Literature India; member, ELO and DHARTI | D6: 2026 | E6: STARS bio (ELO 2026 workshop) | F6: Verified
A7: Desai, Mehulkumar | B7: Editorial | C7: Guest editor, IJHAC special issue 'Digital Futures: Archives, AI, and Access in Indian Digital Humanities' (with Shanmugapriya T, Bhimjyani, Mandal) | D7: forthcoming | E7: STARS bio; IIT Indore DH Lab profile | F7: Verified
A8: Desai, Mehulkumar | B8: Editorial | C8: Co-editor, Digital Creativity special issue 'Interactive Digital Narratives: Creativity, Theory, and Emerging Practices' (with Shanmugapriya T, Marttila, Bouchardon) | D8: CFP 2026 | E8: Taylor & Francis CFP page | F8: Verified
A9: Desai, Mehulkumar | B9: Editorial | C9: Editor-at-Large, Digital Humanities Now | D9: 2026 | E9: STARS bio | F9: Verified
A10: Desai, Mehulkumar | B10: Creative work | C10: The Sacred Sap — Indian Electronic Literature Anthology Vol. 2 | D10: 2026 | E10: Anthology site | F10: Verified
A11: Desai, Mehulkumar | B11: Tool localisation | C11: Gujarati localisation of Voyant Tools (with Bhimjyani) | D11: 2025 | E11: Voyant blog (IEL-037) | F11: Verified
A12: Desai, Mehulkumar | B12: Presentation | C12: ELO 2026: 'Reorienting Electronic Literature' (IEL-029); 'Positioning Electronic literature as an Emerging Creative Industry…' (IEL-030); 'Publishing E-Lit Research in Metric-Driven Academia' (IEL-031) | D12: Jul 2026 | E12: STARS | F12: Verified
A13: Desai, Mehulkumar | B13: Presentation | C13: No presentations before ELO 2026 located in STARS (ELO 2024/2025) or web search | D13: — | E13: Searched 25 Sep 2026 | F13: Gap — ask scholar for CV
A14: Desai, Mehulkumar | B14: Working group | C14: Participant, Critical Code Studies Working Group 2026 | D14: 2026 | E14: CCSWG introductions thread | F14: Verified
A15: Roy, Samya Brata | B15: Editorial | C15: Guest editor (with Hosny & Henrickson), Reviews in Digital Humanities special issue on E-Lit, vol. 7 no. 1 (Jan 2026) | D15: 2026 | E15: Reviews in DH; dh+lib | F15: Verified
... A33: Alagiya, Kavisha | B33: Research focus | C33: PhD (MKBU, supervisor Dilip Barad): Storyspace hypertexts of Joyce and Bernstein; e-lit outputs to date are IEL-027 and IEL-028 | D33: — | E33: STARS bio | F33: Verified

Sheet Verification Log
A1: Verification Log — leads, conflicts, exclusions
A2: Items here are deliberately NOT in Critical Writing until confirmed.
A4: Lead / item | B4: Issue | C4: Next step
A5: Singh, Ritika (2016) | B5: Cited by the SI editorial and by Shanmugapriya & Menon (2018) as an early study; full citation not retrieved. | C5: Obtain reference list of IEL-017 or IEL-002
A6: Rizvi, Zahra & Mukherjee, Souvik (2023) “Your Subaltern is not my Subaltern”, G|A|M|E 10 | B6: Relevant game-narrative study, but excluded because the brief limits Mukherjee to the 2017 article. | C6: Add if the Mukherjee restriction is relaxed
A7: Shanmugapriya T — reviews of 'Tusitala Books' and 'Tamil Digital Heritage Collection', Reviews in Digital Humanities | B7: Listed on DH Lab profile without dates/status. | C7: Check Reviews in DH index
